2024-04-05 04:21:51,776 - ERROR - time data "22.53063540887609" doesn't match format "%Y-%m-%d %H-%M-%S", at position 58. You might want to try:
    - passing `format` if your strings have a consistent format;
    - passing `format='ISO8601'` if your strings are all ISO8601 but not necessarily in exactly the same format;
    - passing `format='mixed'`, and the format will be inferred for each element individually. You might want to use `dayfirst` alongside this.
multiprocessing.pool.RemoteTraceback: 
"""
Traceback (most recent call last):
  File "/usr/local/lib/python3.10/multiprocessing/pool.py", line 125, in worker
    result = (True, func(*args, **kwds))
  File "/usr/local/lib/python3.10/multiprocessing/pool.py", line 48, in mapstar
    return list(map(*args))
  File "/app/3.gen_label.py", line 142, in label_image
    metadata_chunk['timestamp'] = pd.to_datetime(metadata_chunk['timestamp'], format="%Y-%m-%d %H-%M-%S")
  File "/usr/local/lib/python3.10/site-packages/pandas/core/tools/datetimes.py", line 1067, in to_datetime
    values = convert_listlike(arg._values, format)
  File "/usr/local/lib/python3.10/site-packages/pandas/core/tools/datetimes.py", line 433, in _convert_listlike_datetimes
    return _array_strptime_with_fallback(arg, name, utc, format, exact, errors)
  File "/usr/local/lib/python3.10/site-packages/pandas/core/tools/datetimes.py", line 467, in _array_strptime_with_fallback
    result, tz_out = array_strptime(arg, fmt, exact=exact, errors=errors, utc=utc)
  File "strptime.pyx", line 501, in pandas._libs.tslibs.strptime.array_strptime
  File "strptime.pyx", line 451, in pandas._libs.tslibs.strptime.array_strptime
  File "strptime.pyx", line 583, in pandas._libs.tslibs.strptime._parse_with_format
ValueError: time data "22.53063540887609" doesn't match format "%Y-%m-%d %H-%M-%S", at position 58. You might want to try:
    - passing `format` if your strings have a consistent format;
    - passing `format='ISO8601'` if your strings are all ISO8601 but not necessarily in exactly the same format;
    - passing `format='mixed'`, and the format will be inferred for each element individually. You might want to use `dayfirst` alongside this.
"""

The above exception was the direct cause of the following exception:

Traceback (most recent call last):
  File "/app/3.gen_label.py", line 255, in <module>
    results = pool.map(label_image, sub_metadata_chunks)
  File "/usr/local/lib/python3.10/multiprocessing/pool.py", line 367, in map
    return self._map_async(func, iterable, mapstar, chunksize).get()
  File "/usr/local/lib/python3.10/multiprocessing/pool.py", line 774, in get
    raise self._value
ValueError: time data "22.53063540887609" doesn't match format "%Y-%m-%d %H-%M-%S", at position 58. You might want to try:
    - passing `format` if your strings have a consistent format;
    - passing `format='ISO8601'` if your strings are all ISO8601 but not necessarily in exactly the same format;
    - passing `format='mixed'`, and the format will be inferred for each element individually. You might want to use `dayfirst` alongside this.
2024-04-05 04:32:53,821 - ERROR - [Errno 2] No such file or directory: '/app/data/True'
Traceback (most recent call last):
  File "/app/3.gen_label.py", line 145, in label_image
    data = pyart.io.read_sigmet(f"{data_path}/{row['future_path']}")
  File "/usr/local/lib/python3.10/site-packages/pyart/io/sigmet.py", line 131, in read_sigmet
    sigmetfile = SigmetFile(prepare_for_read(filename), debug=debug)
  File "/usr/local/lib/python3.10/site-packages/pyart/io/common.py", line 42, in prepare_for_read
    fh = fsspec.open(filename, mode="rb", compression="infer", **storage_options).open()
  File "/usr/local/lib/python3.10/site-packages/fsspec/core.py", line 135, in open
    return self.__enter__()
  File "/usr/local/lib/python3.10/site-packages/fsspec/core.py", line 103, in __enter__
    f = self.fs.open(self.path, mode=mode)
  File "/usr/local/lib/python3.10/site-packages/fsspec/spec.py", line 1293, in open
    f = self._open(
  File "/usr/local/lib/python3.10/site-packages/fsspec/implementations/local.py", line 197, in _open
    return LocalFileOpener(path, mode, fs=self, **kwargs)
  File "/usr/local/lib/python3.10/site-packages/fsspec/implementations/local.py", line 322, in __init__
    self._open()
  File "/usr/local/lib/python3.10/site-packages/fsspec/implementations/local.py", line 327, in _open
    self.f = open(self.path, mode=self.mode)
FileNotFoundError: [Errno 2] No such file or directory: '/app/data/True'
2024-04-05 04:32:55,347 - ERROR - Error tokenizing data. C error: Expected 7 fields in line 4866, saw 8
Traceback (most recent call last):
  File "/app/3.gen_label.py", line 247, in <module>
    for chunk in metadata_chunks:
  File "/usr/local/lib/python3.10/site-packages/pandas/io/parsers/readers.py", line 1843, in __next__
    return self.get_chunk()
  File "/usr/local/lib/python3.10/site-packages/pandas/io/parsers/readers.py", line 1985, in get_chunk
    return self.read(nrows=size)
  File "/usr/local/lib/python3.10/site-packages/pandas/io/parsers/readers.py", line 1923, in read
    ) = self._engine.read(  # type: ignore[attr-defined]
  File "/usr/local/lib/python3.10/site-packages/pandas/io/parsers/c_parser_wrapper.py", line 234, in read
    chunks = self._reader.read_low_memory(nrows)
  File "parsers.pyx", line 850, in pandas._libs.parsers.TextReader.read_low_memory
  File "parsers.pyx", line 905, in pandas._libs.parsers.TextReader._read_rows
  File "parsers.pyx", line 874, in pandas._libs.parsers.TextReader._tokenize_rows
  File "parsers.pyx", line 891, in pandas._libs.parsers.TextReader._check_tokenize_status
  File "parsers.pyx", line 2061, in pandas._libs.parsers.raise_parser_error
pandas.errors.ParserError: Error tokenizing data. C error: Expected 7 fields in line 4866, saw 8

2024-04-05 04:40:04,460 - ERROR - [Errno 2] No such file or directory: '/app/data/True'
Traceback (most recent call last):
  File "/app/3.gen_label.py", line 145, in label_image
    data = pyart.io.read_sigmet(f"{data_path}/{row['future_path']}")
  File "/usr/local/lib/python3.10/site-packages/pyart/io/sigmet.py", line 131, in read_sigmet
    sigmetfile = SigmetFile(prepare_for_read(filename), debug=debug)
  File "/usr/local/lib/python3.10/site-packages/pyart/io/common.py", line 42, in prepare_for_read
    fh = fsspec.open(filename, mode="rb", compression="infer", **storage_options).open()
  File "/usr/local/lib/python3.10/site-packages/fsspec/core.py", line 135, in open
    return self.__enter__()
  File "/usr/local/lib/python3.10/site-packages/fsspec/core.py", line 103, in __enter__
    f = self.fs.open(self.path, mode=mode)
  File "/usr/local/lib/python3.10/site-packages/fsspec/spec.py", line 1293, in open
    f = self._open(
  File "/usr/local/lib/python3.10/site-packages/fsspec/implementations/local.py", line 197, in _open
    return LocalFileOpener(path, mode, fs=self, **kwargs)
  File "/usr/local/lib/python3.10/site-packages/fsspec/implementations/local.py", line 322, in __init__
    self._open()
  File "/usr/local/lib/python3.10/site-packages/fsspec/implementations/local.py", line 327, in _open
    self.f = open(self.path, mode=self.mode)
FileNotFoundError: [Errno 2] No such file or directory: '/app/data/True'
2024-04-05 04:40:05,978 - ERROR - Error tokenizing data. C error: Expected 7 fields in line 4866, saw 8
Traceback (most recent call last):
  File "/app/3.gen_label.py", line 247, in <module>
    for chunk in metadata_chunks:
  File "/usr/local/lib/python3.10/site-packages/pandas/io/parsers/readers.py", line 1843, in __next__
    return self.get_chunk()
  File "/usr/local/lib/python3.10/site-packages/pandas/io/parsers/readers.py", line 1985, in get_chunk
    return self.read(nrows=size)
  File "/usr/local/lib/python3.10/site-packages/pandas/io/parsers/readers.py", line 1923, in read
    ) = self._engine.read(  # type: ignore[attr-defined]
  File "/usr/local/lib/python3.10/site-packages/pandas/io/parsers/c_parser_wrapper.py", line 234, in read
    chunks = self._reader.read_low_memory(nrows)
  File "parsers.pyx", line 850, in pandas._libs.parsers.TextReader.read_low_memory
  File "parsers.pyx", line 905, in pandas._libs.parsers.TextReader._read_rows
  File "parsers.pyx", line 874, in pandas._libs.parsers.TextReader._tokenize_rows
  File "parsers.pyx", line 891, in pandas._libs.parsers.TextReader._check_tokenize_status
  File "parsers.pyx", line 2061, in pandas._libs.parsers.raise_parser_error
pandas.errors.ParserError: Error tokenizing data. C error: Expected 7 fields in line 4866, saw 8

