2024-08-29 09:36:29,378 - INFO - Using 16bit Automatic Mixed Precision (AMP)
2024-08-29 09:36:29,458 - INFO - GPU available: True (cuda), used: True
2024-08-29 09:36:29,760 - INFO - TPU available: False, using: 0 TPU cores
2024-08-29 09:36:29,760 - INFO - IPU available: False, using: 0 IPUs
2024-08-29 09:36:29,760 - INFO - HPU available: False, using: 0 HPUs
2024-08-29 09:36:29,805 - INFO - You are using a CUDA device ('NVIDIA GeForce RTX 4060 Laptop GPU') that has Tensor Cores. To properly utilize them, you should set `torch.set_float32_matmul_precision('medium' | 'high')` which will trade-off precision for performance. For more details, read https://pytorch.org/docs/stable/generated/torch.set_float32_matmul_precision.html#torch.set_float32_matmul_precision
2024-08-29 09:36:30,965 - INFO - LOCAL_RANK: 0 - CUDA_VISIBLE_DEVICES: [0]
2024-08-29 09:36:30,979 - INFO - 
  | Name  | Type     | Params
-----------------------------------
0 | model | ConvNeXt | 87.6 M
-----------------------------------
87.6 M    Trainable params
0         Non-trainable params
87.6 M    Total params
350.286   Total estimated model params size (MB)
2024-08-29 09:36:31,724 - ERROR - Caught RuntimeError in DataLoader worker process 0.
Original Traceback (most recent call last):
  File "/mnt/c/Users/ASUS/Downloads/Coding/ai-project3/venv/lib/python3.10/site-packages/torch/utils/data/_utils/worker.py", line 308, in _worker_loop
    data = fetcher.fetch(index)
  File "/mnt/c/Users/ASUS/Downloads/Coding/ai-project3/venv/lib/python3.10/site-packages/torch/utils/data/_utils/fetch.py", line 51, in fetch
    data = [self.dataset[idx] for idx in possibly_batched_index]
  File "/mnt/c/Users/ASUS/Downloads/Coding/ai-project3/venv/lib/python3.10/site-packages/torch/utils/data/_utils/fetch.py", line 51, in <listcomp>
    data = [self.dataset[idx] for idx in possibly_batched_index]
  File "/mnt/c/Users/ASUS/Downloads/Coding/ai-project3/_init_model.py", line 218, in __getitem__
    ima_list = [read_image(path) for path in img_paths]
  File "/mnt/c/Users/ASUS/Downloads/Coding/ai-project3/_init_model.py", line 218, in <listcomp>
    ima_list = [read_image(path) for path in img_paths]
  File "/mnt/c/Users/ASUS/Downloads/Coding/ai-project3/venv/lib/python3.10/site-packages/torchvision/io/image.py", line 258, in read_image
    data = read_file(path)
  File "/mnt/c/Users/ASUS/Downloads/Coding/ai-project3/venv/lib/python3.10/site-packages/torchvision/io/image.py", line 52, in read_file
    data = torch.ops.image.read_file(path)
  File "/mnt/c/Users/ASUS/Downloads/Coding/ai-project3/venv/lib/python3.10/site-packages/torch/_ops.py", line 755, in __call__
    return self._op(*args, **(kwargs or {}))
RuntimeError: [Errno 2] No such file or directory: 'image/all/2021-12-16 17-00-43'
Traceback (most recent call last):
  File "/mnt/c/Users/ASUS/Downloads/Coding/ai-project3/_train_model.py", line 220, in <module>
    trainer.fit(module)
  File "/mnt/c/Users/ASUS/Downloads/Coding/ai-project3/venv/lib/python3.10/site-packages/pytorch_lightning/trainer/trainer.py", line 544, in fit
    call._call_and_handle_interrupt(
  File "/mnt/c/Users/ASUS/Downloads/Coding/ai-project3/venv/lib/python3.10/site-packages/pytorch_lightning/trainer/call.py", line 44, in _call_and_handle_interrupt
    return trainer_fn(*args, **kwargs)
  File "/mnt/c/Users/ASUS/Downloads/Coding/ai-project3/venv/lib/python3.10/site-packages/pytorch_lightning/trainer/trainer.py", line 580, in _fit_impl
    self._run(model, ckpt_path=ckpt_path)
  File "/mnt/c/Users/ASUS/Downloads/Coding/ai-project3/venv/lib/python3.10/site-packages/pytorch_lightning/trainer/trainer.py", line 987, in _run
    results = self._run_stage()
  File "/mnt/c/Users/ASUS/Downloads/Coding/ai-project3/venv/lib/python3.10/site-packages/pytorch_lightning/trainer/trainer.py", line 1031, in _run_stage
    self._run_sanity_check()
  File "/mnt/c/Users/ASUS/Downloads/Coding/ai-project3/venv/lib/python3.10/site-packages/pytorch_lightning/trainer/trainer.py", line 1060, in _run_sanity_check
    val_loop.run()
  File "/mnt/c/Users/ASUS/Downloads/Coding/ai-project3/venv/lib/python3.10/site-packages/pytorch_lightning/loops/utilities.py", line 182, in _decorator
    return loop_run(self, *args, **kwargs)
  File "/mnt/c/Users/ASUS/Downloads/Coding/ai-project3/venv/lib/python3.10/site-packages/pytorch_lightning/loops/evaluation_loop.py", line 128, in run
    batch, batch_idx, dataloader_idx = next(data_fetcher)
  File "/mnt/c/Users/ASUS/Downloads/Coding/ai-project3/venv/lib/python3.10/site-packages/pytorch_lightning/loops/fetchers.py", line 133, in __next__
    batch = super().__next__()
  File "/mnt/c/Users/ASUS/Downloads/Coding/ai-project3/venv/lib/python3.10/site-packages/pytorch_lightning/loops/fetchers.py", line 60, in __next__
    batch = next(self.iterator)
  File "/mnt/c/Users/ASUS/Downloads/Coding/ai-project3/venv/lib/python3.10/site-packages/pytorch_lightning/utilities/combined_loader.py", line 341, in __next__
    out = next(self._iterator)
  File "/mnt/c/Users/ASUS/Downloads/Coding/ai-project3/venv/lib/python3.10/site-packages/pytorch_lightning/utilities/combined_loader.py", line 142, in __next__
    out = next(self.iterators[0])
  File "/mnt/c/Users/ASUS/Downloads/Coding/ai-project3/venv/lib/python3.10/site-packages/torch/utils/data/dataloader.py", line 631, in __next__
    data = self._next_data()
  File "/mnt/c/Users/ASUS/Downloads/Coding/ai-project3/venv/lib/python3.10/site-packages/torch/utils/data/dataloader.py", line 1346, in _next_data
    return self._process_data(data)
  File "/mnt/c/Users/ASUS/Downloads/Coding/ai-project3/venv/lib/python3.10/site-packages/torch/utils/data/dataloader.py", line 1372, in _process_data
    data.reraise()
  File "/mnt/c/Users/ASUS/Downloads/Coding/ai-project3/venv/lib/python3.10/site-packages/torch/_utils.py", line 722, in reraise
    raise exception
RuntimeError: Caught RuntimeError in DataLoader worker process 0.
Original Traceback (most recent call last):
  File "/mnt/c/Users/ASUS/Downloads/Coding/ai-project3/venv/lib/python3.10/site-packages/torch/utils/data/_utils/worker.py", line 308, in _worker_loop
    data = fetcher.fetch(index)
  File "/mnt/c/Users/ASUS/Downloads/Coding/ai-project3/venv/lib/python3.10/site-packages/torch/utils/data/_utils/fetch.py", line 51, in fetch
    data = [self.dataset[idx] for idx in possibly_batched_index]
  File "/mnt/c/Users/ASUS/Downloads/Coding/ai-project3/venv/lib/python3.10/site-packages/torch/utils/data/_utils/fetch.py", line 51, in <listcomp>
    data = [self.dataset[idx] for idx in possibly_batched_index]
  File "/mnt/c/Users/ASUS/Downloads/Coding/ai-project3/_init_model.py", line 218, in __getitem__
    ima_list = [read_image(path) for path in img_paths]
  File "/mnt/c/Users/ASUS/Downloads/Coding/ai-project3/_init_model.py", line 218, in <listcomp>
    ima_list = [read_image(path) for path in img_paths]
  File "/mnt/c/Users/ASUS/Downloads/Coding/ai-project3/venv/lib/python3.10/site-packages/torchvision/io/image.py", line 258, in read_image
    data = read_file(path)
  File "/mnt/c/Users/ASUS/Downloads/Coding/ai-project3/venv/lib/python3.10/site-packages/torchvision/io/image.py", line 52, in read_file
    data = torch.ops.image.read_file(path)
  File "/mnt/c/Users/ASUS/Downloads/Coding/ai-project3/venv/lib/python3.10/site-packages/torch/_ops.py", line 755, in __call__
    return self._op(*args, **(kwargs or {}))
RuntimeError: [Errno 2] No such file or directory: 'image/all/2021-12-16 17-00-43'

