2024-04-21 04:44:51,482 - ERROR - (0         False
1         False
2         False
3         False
4         False
          ...  
251474    False
251475    False
251476    False
251477    False
251478    False
Name: timestamp_0, Length: 251479, dtype: bool, 'avg_reflectivity_0')
multiprocessing.pool.RemoteTraceback: 
"""
Traceback (most recent call last):
  File "/opt/conda/lib/python3.10/site-packages/pandas/core/indexes/base.py", line 3805, in get_loc
    return self._engine.get_loc(casted_key)
  File "index.pyx", line 167, in pandas._libs.index.IndexEngine.get_loc
  File "index.pyx", line 173, in pandas._libs.index.IndexEngine.get_loc
TypeError: '(0         False
1         False
2         False
3         False
4         False
          ...  
251474    False
251475    False
251476    False
251477    False
251478    False
Name: timestamp_0, Length: 251479, dtype: bool, 'avg_reflectivity_0')' is an invalid key

During handling of the above exception, another exception occurred:

Traceback (most recent call last):
  File "/opt/conda/lib/python3.10/multiprocessing/pool.py", line 125, in worker
    result = (True, func(*args, **kwds))
  File "/opt/conda/lib/python3.10/multiprocessing/pool.py", line 48, in mapstar
    return list(map(*args))
  File "/app/3.gen_label.py", line 181, in find_future_images
    metadata.loc[idx, [avg_reflectivity_col]] = metadata[metadata['timestamp_0'] == future_timestamp, 'avg_reflectivity_0'].tolist()[0]
  File "/opt/conda/lib/python3.10/site-packages/pandas/core/frame.py", line 4090, in __getitem__
    indexer = self.columns.get_loc(key)
  File "/opt/conda/lib/python3.10/site-packages/pandas/core/indexes/base.py", line 3817, in get_loc
    self._check_indexing_error(key)
  File "/opt/conda/lib/python3.10/site-packages/pandas/core/indexes/base.py", line 6059, in _check_indexing_error
    raise InvalidIndexError(key)
pandas.errors.InvalidIndexError: (0         False
1         False
2         False
3         False
4         False
          ...  
251474    False
251475    False
251476    False
251477    False
251478    False
Name: timestamp_0, Length: 251479, dtype: bool, 'avg_reflectivity_0')
"""

The above exception was the direct cause of the following exception:

Traceback (most recent call last):
  File "/app/3.gen_label.py", line 254, in <module>
    pool.map(find_future_images, [7200, 21600, 43200])
  File "/opt/conda/lib/python3.10/multiprocessing/pool.py", line 367, in map
    return self._map_async(func, iterable, mapstar, chunksize).get()
  File "/opt/conda/lib/python3.10/multiprocessing/pool.py", line 774, in get
    raise self._value
pandas.errors.InvalidIndexError: (0         False
1         False
2         False
3         False
4         False
          ...  
251474    False
251475    False
251476    False
251477    False
251478    False
Name: timestamp_0, Length: 251479, dtype: bool, 'avg_reflectivity_0')
